Workbook

Sheet Vertical Analysis
B2: Vertical Analysis
B4: in millions
B5: Fiscal Year | C5: 2020 | D5: 2021 | E5: 2022 | F5: 2023 | G5: 2024 | I5: Fiscal Year | J5: 2020 | K5: 2021 | L5: 2022 | M5: 2023 | N5: 2024
B6: Net Sales | C6: 1216.1 | D6: 1391.5 | E6: 1668.3 | F6: 1692.1 | G6: 1406.4 | I6: Net Sales | J6: =ROUND(D6/D6, 2) -> 1 | K6: =ROUND(D6/D6, 4) -> 1 | L6: =ROUND(E6/$E$6,4) -> 1 | M6: =ROUND(F6/$F$6, 4) -> 1 | N6: =ROUND(G6/$G$6, 4) -> 1
B7: Cost of Sales | C7: 750.6 | D7: 878.7 | E7: 1098.2 | F7: 1220.2 | G7: 951.7 | I7: Cost of Sales | J7: =ROUND(C7/$C$6, 4) -> 0.6172 | K7: =ROUND(D7/$D$6, 4) -> 0.6315 | L7: =ROUND(E7/$E$6,4) -> 0.6583 | M7: =ROUND(F7/$F$6, 4) -> 0.7211 | N7: =ROUND(G7/$G$6, 4) -> 0.6767
B8: Gross Profit | C8: 465.5 | D8: 512.8 | E8: 570.1 | F8: 471.9 | G8: 454.7 | I8: Gross Profit | J8: =ROUND(C8/$C$6, 4) -> 0.3828 | K8: =ROUND(D8/$D$6, 4) -> 0.3685 | L8: =ROUND(E8/$E$6,4) -> 0.3417 | M8: =ROUND(F8/$F$6, 4) -> 0.2789 | N8: =ROUND(G8/$G$6, 4) -> 0.3233
B9: Selling, general, and administrative | C9: 149.4 | D9: 179.3 | E9: 198.8 | F9: 183.7 | G9: 166.7 | I9: Selling, general, and administrative | J9: =ROUND(C9/$C$6, 4) -> 0.1229 | K9: =ROUND(D9/$D$6, 4) -> 0.1289 | L9: =ROUND(E9/$E$6,4) -> 0.1192 | M9: =ROUND(F9/$F$6, 4) -> 0.1086 | N9: =ROUND(G9/$G$6, 4) -> 0.1185
B10: Research and technical expenses | C10: 22.6 | D10: 26.3 | E10: 30.3 | F10: 31.8 | G10: 28.1 | I10: Research and technical expenses | J10: =ROUND(C10/$C$6, 4) -> 0.0186 | K10: =ROUND(D10/$D$6, 4) -> 0.0189 | L10: =ROUND(E10/$E$6,4) -> 0.0182 | M10: =ROUND(F10/$F$6, 4) -> 0.0188 | N10: =ROUND(G10/$G$6, 4) -> 0.02
B11: Restructing and other (income) charges | C11: 18.5 | D11: 16.2 | E11: 13.8 | F11: 170.2 | G11: 186.2 | I11: Restructing and other (income) charges | J11: =ROUND(C11/$C$6, 4) -> 0.0152 | K11: =ROUND(D11/$D$6, 4) -> 0.0116 | L11: =ROUND(E11/$E$6,4) -> 0.0083 | M11: =ROUND(F11/$F$6, 4) -> 0.1006 | N11: =ROUND(G11/$G$6, 4) -> 0.1324
B12: Goodwill impairment charge | G12: 349.1 | I12: Goodwill impairment charge | J12: =ROUND(C12/$C$6, 4) -> 0 | K12: =ROUND(D12/$D$6, 4) -> 0 | L12: =ROUND(E12/$E$6,4) -> 0 | M12: =ROUND(F12/$F$6, 4) -> 0 | N12: =ROUND(G12/$G$6, 4) -> 0.2482
B13: Acquisition-related costs | C13: 1.8 | D13: 0.6 | E13: 5 | F13: 3.6 | G13: 0.3 | I13: Acquisition-related costs | J13: =ROUND(C13/$C$6, 4) -> 0.0015 | K13: =ROUND(D13/$D$6, 4) -> 0.0004 | L13: =ROUND(E13/$E$6,4) -> 0.003 | M13: =ROUND(F13/$F$6, 4) -> 0.0021 | N13: =ROUND(G13/$G$6, 4) -> 0.0002
B14: Other (income) expense, net | C14: -4.1 | D14: 79.9 | E14: -1.7 | F14: 5.7 | G14: 169.8 | I14: Other (income) expense, net | J14: =ROUND(C14/$C$6, 4) -> -0.0034 | K14: =ROUND(D14/$D$6, 4) -> 0.0574 | L14: =ROUND(E14/$E$6,4) -> -0.001 | M14: =ROUND(F14/$F$6, 4) -> 0.0034 | N14: =ROUND(G14/$G$6, 4) -> 0.1207
B15: Interest expense | C15: 47.1 | D15: 51.7 | E15: 61.8 | F15: 93.3 | G15: 97.8 | I15: Interest expense | J15: =ROUND(C15/$C$6, 4) -> 0.0387 | K15: =ROUND(D15/$D$6, 4) -> 0.0372 | L15: =ROUND(E15/$E$6,4) -> 0.037 | M15: =ROUND(F15/$F$6, 4) -> 0.0551 | N15: =ROUND(G15/$G$6, 4) -> 0.0695
B16: Interest income | C16: -4.9 | D16: -4 | E16: -7.5 | F16: -6.3 | G16: -7.7 | I16: Interest income | J16: =ROUND(C16/$C$6, 4) -> -0.004 | K16: =ROUND(D16/$D$6, 4) -> -0.0029 | L16: =ROUND(E16/$E$6,4) -> -0.0045 | M16: =ROUND(F16/$F$6, 4) -> -0.0037 | N16: =ROUND(G16/$G$6, 4) -> -0.0055
B17: Income (loss) before income taxes | C17: 235.1 | D17: 162.8 | E17: 269.6 | F17: -10.1 | G17: -535.6 | I17: Income (loss) before income taxes | J17: =ROUND(C17/$C$6, 4) -> 0.1933 | K17: =ROUND(D17/$D$6, 4) -> 0.117 | L17: =ROUND(E17/$E$6,4) -> 0.1616 | M17: =ROUND(F17/$F$6, 4) -> -0.006 | N17: =ROUND(G17/$G$6, 4) -> -0.3808
B18: Provision (benefit) for income taxes | C18: 53.7 | D18: 44.7 | E18: 58 | F18: -4.7 | G18: -105.3 | I18: Provision (benefit) for income taxes | J18: =ROUND(C18/$C$6, 4) -> 0.0442 | K18: =ROUND(D18/$D$6, 4) -> 0.0321 | L18: =ROUND(E18/$E$6,4) -> 0.0348 | M18: =ROUND(F18/$F$6, 4) -> -0.0028 | N18: =ROUND(G18/$G$6, 4) -> -0.0749
B19: Net Income (loss) | C19: 181.4 | D19: 118.1 | E19: 211.6 | F19: -5.4 | G19: -430.3 | I19: Net Income (loss) | J19: =ROUND(C19/$C$6, 4) -> 0.1492 | K19: =ROUND(D19/$D$6, 4) -> 0.0849 | L19: =ROUND(E19/$E$6,4) -> 0.1268 | M19: =ROUND(F19/$F$6*100,2) -> -0.32 | N19: =ROUND(G19/$G$6, 4) -> -0.306
I20: Net Margin Percentage | J20: =ROUND(C19/C6, 4) -> 0.1492 | K20: =ROUND(D19/D6, 4) -> 0.0849 | L20: =ROUND(E19/E6, 4) -> 0.1268 | M20: =ROUND(F19/F6, 4) -> -0.0032 | N20: =ROUND(G19/G6, 4) -> -0.306
B21: Operating Income | C21: 2020 | D21: 2021 | E21: 2022 | F21: 2023 | G21: 2024
B22: Gross Profit | C22: 465.5 | D22: 512.8 | E22: 570.1 | F22: 471.9 | G22: 454.7
B23: less SG&A | C23: 149.4 | D23: 179.3 | E23: 198.8 | F23: 183.7 | G23: 166.7
B24: less Research and Technical | C24: 22.6 | D24: 26.3 | E24: 30.3 | F24: 31.8 | G24: 28.1
B25: less Restructuring and other income charges | C25: 18.5 | D25: 16.2 | E25: 13.8 | F25: 170.2 | G25: 186.2
B26: less Goodwill Impairment Charge | G26: 349.1
B27: less Acquisition-Related Costs | C27: 1.8 | D27: 0.6 | E27: 5 | F27: 3.6 | G27: 0.3
B28: less Other Income Expenses | C28: -4.1 | D28: 79.9 | E28: -1.7 | F28: 5.7 | G28: 169.8
B29: Operating Income | C29: =C22-C23-C24-C25-C26-C27-C28 -> 277.3 | D29: =D22-D23-D24-D25-D26-D27-D28 -> 210.5 | E29: =E22-E23-E24-E25-E26-E27-E28 -> 323.9 | F29: =F22-F23-F24-F25-F26-F27-F28 -> 76.9 | G29: =G22-G23-G24-G25-G26-G27-G28 -> -445.5
B30: Operating Margin Percentage | C30: =C29/C6 -> 0.22802401 | D30: =D29/D6 -> 0.1512756 | E30: =E29/E6 -> 0.19414973 | F30: =F29/F6 -> 0.045446487 | G30: =G29/G6 -> -0.31676621

Sheet Horizontal Analysis
B6: Horizontal Analysis
B13: Income Statement | I13: Percent Change Year Over Year
B14: Fiscal Year | C14: 2020 | D14: 2021 | E14: 2022 | F14: 2023 | G14: 2024 | I14: Fiscal Year | J14: 2020 | K14: 2021 | L14: 2022 | M14: 2023 | N14: 2024
B15: Net Sales | C15: 1216.1 | D15: 1391.5 | E15: 1668.3 | F15: 1692.1 | G15: 1406.4 | I15: Net Sales | K15: =ROUND((D15-C15)/C15, 4) -> 0.1442 | L15: =ROUND((E15-D15)/D15, 4) -> 0.1989 | M15: =ROUND((F15-E15)/E15, 4) -> 0.0143 | N15: =ROUND((G15-F15)/F15,4) -> -0.1688
B16: Cost of Sales | C16: 750.6 | D16: 878.7 | E16: 1098.2 | F16: 1220.2 | G16: 951.7 | I16: Cost of Sales | K16: =ROUND((D16-C16)/C16, 4) -> 0.1707 | L16: =ROUND((E16-D16)/D16, 4) -> 0.2498 | M16: =ROUND((F16-E16)/E16, 4) -> 0.1111 | N16: =ROUND((G16-F16)/F16,4) -> -0.22
B17: Gross Profit | C17: 465.5 | D17: 512.8 | E17: 570.1 | F17: 471.9 | G17: 454.7 | I17: Gross Profit | K17: =ROUND((D17-C17)/C17, 4) -> 0.1016 | L17: =ROUND((E17-D17)/D17, 4) -> 0.1117 | M17: =ROUND((F17-E17)/E17, 4) -> -0.1723 | N17: =ROUND((G17-F17)/F17,4) -> -0.0364
B18: Selling, general, and administrative | C18: 149.4 | D18: 179.3 | E18: 198.8 | F18: 183.7 | G18: 166.7 | I18: Selling, general, and administrative | K18: =ROUND((D18-C18)/C18, 4) -> 0.2001 | L18: =ROUND((E18-D18)/D18, 4) -> 0.1088 | M18: =ROUND((F18-E18)/E18, 4) -> -0.076 | N18: =ROUND((G18-F18)/F18,4) -> -0.0925
B19: Research and technical expenses | C19: 22.6 | D19: 26.3 | E19: 30.3 | F19: 31.8 | G19: 28.1 | I19: Research and technical expenses | K19: =ROUND((D19-C19)/C19, 4) -> 0.1637 | L19: =ROUND((E19-D19)/D19, 4) -> 0.1521 | M19: =ROUND((F19-E19)/E19, 4) -> 0.0495 | N19: =ROUND((G19-F19)/F19,4) -> -0.1164
B20: Restructing and other (income) charges | C20: 18.5 | D20: 16.2 | E20: 13.8 | F20: 170.2 | G20: 186.2 | I20: Restructing and other (income) charges | K20: =ROUND((D20-C20)/C20, 4) -> -0.1243 | L20: =ROUND((E20-D20)/D20, 4) -> -0.1481 | M20: =ROUND((F20-E20)/E20, 4) -> 11.3333 | N20: =ROUND((G20-F20)/F20,4) -> 0.094
B21: Goodwill impairment charge | G21: 349.1 | I21: Goodwill impairment charge
B22: Acquisition-related costs | C22: 1.8 | D22: 0.6 | E22: 5 | F22: 3.6 | G22: 0.3 | I22: Acquisition-related costs | K22: =ROUND((D22-C22)/C22, 4) -> -0.6667 | L22: =ROUND((E22-D22)/D22, 4) -> 7.3333 | M22: =ROUND((F22-E22)/E22, 4) -> -0.28 | N22: =ROUND((G22-F22)/F22,4) -> -0.9167
B23: Other (income) expense, net | C23: -4.1 | D23: 79.9 | E23: -1.7 | F23: 5.7 | G23: 169.8 | I23: Other (income) expense, net | K23: =ROUND((D23-C23)/C23, 4) -> -20.4878 | L23: =ROUND((E23-D23)/D23, 4) -> -1.0213 | M23: =ROUND((F23-E23)/E23, 4) -> -4.3529 | N23: =ROUND((G23-F23)/F23,4) -> 28.7895
B24: Interest expense | C24: 47.1 | D24: 51.7 | E24: 61.8 | F24: 93.3 | G24: 97.8 | I24: Interest expense | K24: =ROUND((D24-C24)/C24, 4) -> 0.0977 | L24: =ROUND((E24-D24)/D24, 4) -> 0.1954 | M24: =ROUND((F24-E24)/E24, 4) -> 0.5097 | N24: =ROUND((G24-F24)/F24,4) -> 0.0482
B25: Interest income | C25: -4.9 | D25: -4 | E25: -7.5 | F25: -6.3 | G25: -7.7 | I25: Interest income | K25: =ROUND((D25-C25)/C25, 4) -> -0.1837 | L25: =ROUND((E25-D25)/D25, 4) -> 0.875 | M25: =ROUND((F25-E25)/E25, 4) -> -0.16 | N25: =ROUND((G25-F25)/F25,4) -> 0.2222
B26: Income (loss) before income taxes | C26: 235.1 | D26: 162.8 | E26: 269.6 | F26: -10.1 | G26: -535.6 | I26: Income (loss) before income taxes | K26: =ROUND((D26-C26)/C26, 4) -> -0.3075 | L26: =ROUND((E26-D26)/D26, 4) -> 0.656 | M26: =ROUND((F26-E26)/E26, 4) -> -1.0375 | N26: =ROUND((G26-F26)/F26,4) -> 52.0297
B27: Provision (benefit) for income taxes | C27: 53.7 | D27: 44.7 | E27: 58 | F27: -4.7 | G27: -105.3 | I27: Provision (benefit) for income taxes | K27: =ROUND((D27-C27)/C27, 4) -> -0.1676 | L27: =ROUND((E27-D27)/D27, 4) -> 0.2975 | M27: =ROUND((F27-E27)/E27, 4) -> -1.081 | N27: =ROUND((G27-F27)/F27,4) -> 21.4043
B28: Net Income (loss) | C28: 181.4 | D28: 118.1 | E28: 211.6 | F28: -5.4 | G28: -430.3 | I28: Net Income (loss) | K28: =ROUND((D28-C28)/C28, 4) -> -0.349 | L28: =ROUND((E28-D28)/D28, 4) -> 0.7917 | M28: =ROUND((F28-E28)/E28, 4) -> -1.0255 | N28: =ROUND((G28-F28)/F28,4) -> 78.6852
B31: Percent Change Since 2020
B32: Fiscal Year | C32: 2020 | D32: 2021 | E32: 2022 | F32: 2023 | G32: 2024
B33: Net Sales | D33: =ROUND((D15-C15)/C15, 4) -> 0.1442 | E33: =ROUND((E15-C15)/C15, 4) -> 0.3718 | F33: =ROUND((F15-C15)/C15, 4) -> 0.3914 | G33: =ROUND((G15-C15)/C15,4) -> 0.1565
B34: Cost of Sales | D34: =ROUND((D16-C16)/C16, 4) -> 0.1707 | E34: =ROUND((E16-C16)/C16, 4) -> 0.4631 | F34: =ROUND((F16-C16)/C16, 4) -> 0.6256 | G34: =ROUND((G16-C16)/C16,4) -> 0.2679
B35: Gross Profit | D35: =ROUND((D17-C17)/C17, 4) -> 0.1016 | E35: =ROUND((E17-C17)/C17, 4) -> 0.2247 | F35: =ROUND((F17-C17)/C17, 4) -> 0.0137 | G35: =ROUND((G17-C17)/C17,4) -> -0.0232
B36: Selling, general, and administrative | D36: =ROUND((D18-C18)/C18, 4) -> 0.2001 | E36: =ROUND((E18-C18)/C18, 4) -> 0.3307 | F36: =ROUND((F18-C18)/C18, 4) -> 0.2296 | G36: =ROUND((G18-C18)/C18,4) -> 0.1158
B37: Research and technical expenses | D37: =ROUND((D19-C19)/C19, 4) -> 0.1637 | E37: =ROUND((E19-C19)/C19, 4) -> 0.3407 | F37: =ROUND((F19-C19)/C19, 4) -> 0.4071 | G37: =ROUND((G19-C19)/C19,4) -> 0.2434
B38: Restructing and other (income) charges | D38: =ROUND((D20-C20)/C20, 4) -> -0.1243 | E38: =ROUND((E20-C20)/C20, 4) -> -0.2541 | F38: =ROUND((F20-C20)/C20, 4) -> 8.2 | G38: =ROUND((G20-C20)/C20,4) -> 9.0649
B39: Goodwill impairment charge
B40: Acquisition-related costs | D40: =ROUND((D22-C22)/C22, 4) -> -0.6667 | E40: =ROUND((E22-C22)/C22, 4) -> 1.7778 | F40: =ROUND((F22-C22)/C22, 4) -> 1 | G40: =ROUND((G22-C22)/C22,4) -> -0.8333
B41: Other (income) expense, net | D41: =ROUND((D23-C23)/C23, 4) -> -20.4878 | E41: =ROUND((E23-C23)/C23, 4) -> -0.5854 | F41: =ROUND((F23-C23)/C23, 4) -> -2.3902 | G41: =ROUND((G23-C23)/C23,4) -> -42.4146
B42: Interest expense | D42: =ROUND((D24-C24)/C24, 4) -> 0.0977 | E42: =ROUND((E24-C24)/C24, 4) -> 0.3121 | F42: =ROUND((F24-C24)/C24, 4) -> 0.9809 | G42: =ROUND((G24-C24)/C24,4) -> 1.0764
B43: Interest income | D43: =ROUND((D25-C25)/C25, 4) -> -0.1837 | E43: =ROUND((E25-C25)/C25, 4) -> 0.5306 | F43: =ROUND((F25-C25)/C25, 4) -> 0.2857 | G43: =ROUND((G25-C25)/C25,4) -> 0.5714
B44: Income (loss) before income taxes | D44: =ROUND((D26-C26)/C26, 4) -> -0.3075 | E44: =ROUND((E26-C26)/C26, 4) -> 0.1467 | F44: =ROUND((F26-C26)/C26, 4) -> -1.043 | G44: =ROUND((G26-C26)/C26,4) -> -3.2782
B45: Provision (benefit) for income taxes | D45: =ROUND((D27-C27)/C27, 4) -> -0.1676 | E45: =ROUND((E27-C27)/C27, 4) -> 0.0801 | F45: =ROUND((F27-C27)/C27, 4) -> -1.0875 | G45: =ROUND((G27-C27)/C27,4) -> -2.9609
B46: Net Income (loss) | D46: =ROUND((D28-C28)/C28, 4) -> -0.349 | E46: =ROUND((E28-C28)/C28, 4) -> 0.1665 | F46: =ROUND((F28-C28)/C28, 4) -> -1.0298 | G46: =ROUND((G28-C28)/C28,4) -> -3.3721
B49: 2025 Net Sales | C49: Q1 | D49: Q2 | E49: Q3
C50: 284 | D50: 365.1 | E50: 333.1
D51: =(D50-C50)/C50 -> 0.28556338 | E51: =(E50-D50)/D50 -> -0.08764722
B53: Comparing Cost of Sales 2024 vs. 2025
C54: Nine Months Ended September 30,
C55: 2024 | D55: 2025
B56: Cost of Sales | C56: 571.9 | D56: 538.8
...

Sheet Sales Breakdown
B3: Sales by Segment, Sales by Region, and Segment Composition
B5: Total Performance Materials
D7: Year | E7: 2020 | F7: 2021 | G7: 2022 | H7: 2023 | I7: 2024
D8: Net Sales | E8: 510 | F8: 516.8 | G8: 548.5 | H8: 586 | I8: 609.6
D9: Segment EBITDA | E9: 249.2 | F9: 249.4 | G9: 252.2 | H9: 286.6 | I9: 319.1
D11: Year | E11: 2020 | F11: 2021 | G11: 2022 | H11: 2023 | I11: 2024
D12: Net Sales | F12: =ROUND((F8-E8)/E8, 4) -> 0.0133 | G12: =ROUND((G8-F8)/F8, 4) -> 0.0613 | H12: =ROUND((H8-G8)/G8,4) -> 0.0684 | I12: =ROUND((I8-H8)/H8,4) -> 0.0403
D13: Segment EBITDA | F13: =ROUND((F9-E9)/E9, 4) -> 0.0008 | G13: =ROUND((G9-F9)/F9, 4) -> 0.0112 | H13: =ROUND((H9-G9)/G9,4) -> 0.1364 | I13: =ROUND((I9-H9)/H9,4) -> 0.1134
B15: Performance Chemicals
D17: Year | E17: 2020 | F17: 2021 | G17: 2022 | H17: 2023 | I17: 2024
D18: Net Sales | E18: 706.1 | F18: 874.7 | G18: 875.1 | H18: 902.1 | I18: 608.2
D19: Road Technolies product line | G19: 241.3 | H19: 369.8 | I19: 342.3
D20: Industrial Specialities product line | G20: 633.8 | H20: 532.3 | I20: 265.9
D21: Segment EBITDA | E21: 148.7 | F21: 172.8 | G21: 160.4 | H21: 65.7 | I21: 14.7
D23: Year | E23: 2020 | F23: 2021 | G23: 2022 | H23: 2023 | I23: 2024
D24: Net Sales | F24: =ROUND((F18-E18)/E18,4) -> 0.2388 | G24: =ROUND((G18-F18)/F18, 4) -> 0.0005 | H24: =ROUND((H18-G18)/G18,4) -> 0.0309 | I24: =ROUND((I18-H18)/H18,4) -> -0.3258
D25: Road Technolies product line | H25: =ROUND((H19-G19)/G19,4) -> 0.5325 | I25: =ROUND((I19-H19)/H19,4) -> -0.0744
D26: Industrial Specialities product line | H26: =ROUND((H20-G20)/G20,4) -> -0.1601 | I26: =ROUND((I20-H20)/H20,4) -> -0.5005
D27: Segment EBITDA | F27: =ROUND((F21-E21)/E21,4) -> 0.1621 | G27: =ROUND((G21-F21)/F21, 4) -> -0.0718 | H27: =ROUND((H21-G21)/G21,4) -> -0.5904 | I27: =ROUND((I21-H21)/H21,4) -> -0.7763
B29: Advanced Polymer Technologies
D31: Year | E31: 2022 | F31: 2023 | G31: 2024
D32: Net Sales | E32: 244.7 | F32: 204 | G32: 188.6
D33: Segment EBITDA | E33: 40 | F33: 44.5 | G33: 35.2
D35: Year | E35: 2022 | F35: 2023 | G35: 2024
D36: Net Sales | F36: =ROUND((F32-E32)/E32,4) -> -0.1663 | G36: =ROUND((G32-F32)/F32,4) -> -0.0755
D37: Segment EBITDA | F37: =ROUND((F33-E33)/E33,4) -> 0.1125 | G37: =ROUND((G33-F33)/F33,4) -> -0.209
B41: Regional Net Sales | D41: Year | E41: 2022 | F41: 2023 | G41: 2024
D42: North America | E42: 983.2 | F42: 1069.5 | G42: 820.9
D43: Asia Pacific | E43: 398.7 | F43: 364 | G43: 346
D44: Europe, Middle East, Africa | E44: 242.2 | F44: 215.5 | G44: 187
D45: South America | E45: 44.2 | F45: 43.1 | G45: 52.5
D47: Year | E47: 2022 | F47: 2023 | G47: 2024
D48: North America | F48: =ROUND((F42-E42)/E42,4) -> 0.0878 | G48: =ROUND((G42-F42)/F42,4) -> -0.2324
D49: Asia Pacific | F49: =ROUND((F43-E43)/E43,4) -> -0.087 | G49: =ROUND((G43-F43)/F43,4) -> -0.0495
D50: Europe, Middle East, Africa | F50: =ROUND((F44-E44)/E44,4) -> -0.1102 | G50: =ROUND((G44-F44)/F44,4) -> -0.1323
D51: South America | F51: =ROUND((F45-E45)/E45,4) -> -0.0249 | G51: =ROUND((G45-F45)/F45,4) -> 0.2181
D53: Year | E53: 2022 | F53: 2023 | G53: 2024
D54: North America | E54: =ROUND((E42/$E$58), 4) -> 0.5893 | F54: =ROUND((F42/$F$58),4) -> 0.6321 | G54: =ROUND((G42/$G$58),4) -> 0.5837
D55: Asia Pacific | E55: =ROUND((E43/$E$58), 4) -> 0.239 | F55: =ROUND((F43/$F$58),4) -> 0.2151 | G55: =ROUND((G43/$G$58),4) -> 0.246
D56: Europe, Middle East, Africa | E56: =ROUND((E44/$E$58), 4) -> 0.1452 | F56: =ROUND((F44/$F$58),4) -> 0.1274 | G56: =ROUND((G44/$G$58),4) -> 0.133
...

Sheet Ratios
C4: Year | D4: Net Sales (actual) | E4: Revenue Growth %
C5: 2020 | D5: 1216.1
C6: 2021 | D6: 1391.5 | E6: =ROUND((D6-D5)/D6,4) -> 0.1261
C7: 2022 | D7: 1668.3 | E7: =ROUND((D7-D6)/D7,4) -> 0.1659
C8: 2023 | D8: 1692.1 | E8: =ROUND((D8-D7)/D8,4) -> 0.0141
C9: 2024 | D9: 1406.4 | E9: =ROUND((D9-D8)/D9,4) -> -0.2031
C12: Margin/Ratio | D12: 2020 | E12: 2021 | F12: 2022 | G12: 2023 | H12: 2024
C13: Gross Margin % | D13: 0.3828 | E13: 0.3685 | F13: 0.3417 | G13: 0.2789 | H13: 0.3233
C14: SG&A % of Sales | D14: 0.1229 | E14: 0.1289 | F14: 0.1192 | G14: 0.1086 | H14: 0.1185
C15: R&D of Sales | D15: 0.0186 | E15: 0.0189 | F15: 0.0182 | G15: 0.0188 | H15: 0.02
C16: Operating Margin % | D16: 0.22802401 | E16: 0.1512756 | F16: 0.19414973 | G16: 0.045446487 | H16: -0.31676621
C17: Net Margin % | D17: 0.1492 | E17: 0.0849 | F17: 0.1268 | G17: -0.0032 | H17: -0.306

Sheet Revenue Build
B3: Revenue Build
B6: Fiscal Year | C6: 2020 | D6: 2021 | E6: 2022 | F6: 2023 | G6: 2024 | H6: 2025 | I6: 2026 | J6: 2027 | K6: 2028 | L6: 2029 | M6: CAGR
B7: Perfomance Materials | C7: 510 | D7: 516.8 | E7: 548.5 | F7: 586 | G7: 609.6 | H7: 637.40234 | I7: 666.47268 | J7: 696.86884 | K7: 728.65129 | L7: 761.88327 | M7: =(G7/C7)^(1/(5-1))-1 -> 0.045607514
B8: year over year growth | D8: =ROUND((D7-C7)/C7,4) -> 0.0133 | E8: =ROUND((E7-D7)/D7,4) -> 0.0613 | F8: =ROUND((F7-E7)/E7,4) -> 0.0684 | G8: =ROUND((G7-F7)/F7,4) -> 0.0403 | H8: =ROUND((H7-G7)/G7,4) -> 0.0456 | I8: =ROUND((I7-H7)/H7,4) -> 0.0456 | J8: =ROUND((J7-I7)/I7,4) -> 0.0456 | K8: =ROUND((K7-J7)/J7,4) -> 0.0456 | L8: =ROUND((L7-K7)/K7,4) -> 0.0456
B10: Performance Chemicals | C10: 706.1 | D10: 874.7 | E10: 875.1 | F10: 902.1 | G10: 608.2 | H10: =H12+H14 -> 542.6 | I10: =I12 -> 439.9 | J10: =J12 -> 466.294 | K10: =K12 -> 494.27164 | L10: =L12 -> 523.92794
B11: year over year growth | D11: =ROUND((D10-C10)/C10,4) -> 0.2388 | E11: =ROUND((E10-D10)/D10,4) -> 0.0005 | F11: =ROUND((F10-E10)/E10,4) -> 0.0309 | G11: =ROUND((G10-F10)/F10,4) -> -0.3258 | H11: =ROUND((H10-G10)/G10,4) -> -0.1079 | I11: =ROUND((I10-H10)/H10,4) -> -0.1893 | J11: =ROUND((J10-I10)/I10,4) -> 0.06 | K11: =ROUND((K10-J10)/J10,4) -> 0.06 | L11: =ROUND((L10-K10)/K10,4) -> 0.06
B12: Road Technolies product line | E12: 241.3 | F12: 369.8 | G12: 342.3 | H12: 415 | I12: =H12*(1+0.06) -> 439.9 | J12: =I12*(1+0.06) -> 466.294 | K12: =J12*(1+0.06) -> 494.27164 | L12: =K12*(1+0.06) -> 523.92794
H13: =ROUND((H12-G12)/G12,4) -> 0.2124 | I13: =ROUND((I12-H12)/H12,4) -> 0.06 | J13: =ROUND((J12-I12)/I12,4) -> 0.06 | K13: =ROUND((K12-J12)/J12,4) -> 0.06 | L13: =ROUND((L12-K12)/K12,4) -> 0.06
B14: Industrial Specialities product line | E14: 633.8 | F14: 532.3 | G14: 265.9 | H14: 127.6 | I14: 0 | J14: 0 | K14: 0 | L14: 0
B17: Advanced Polymer Technology | E17: 244.7 | F17: 204 | G17: 188.6 | H17: =G17*(1+$M$17) -> 165.5753 | I17: =H17*(1+$M$17) -> 145.3615 | J17: 137 | K17: 135 | L17: 132 | M17: =(G17/E17)^(1/(3-1))-1 -> -0.12208219
B18: year over year growth | F18: =ROUND((F17-E17)/E17, 4) -> -0.1663 | G18: =ROUND((G17-F17)/F17, 4) -> -0.0755 | H18: =ROUND((H17-G17)/G17, 4) -> -0.1221 | I18: =ROUND((I17-H17)/H17, 4) -> -0.1221 | J18: =ROUND((J17-I17)/I17, 4) -> -0.0575 | K18: =ROUND((K17-J17)/J17, 4) -> -0.0146 | L18: =ROUND((L17-K17)/K17, 4) -> -0.0222
B20: Total Sales | C20: =SUM(C7,C10,C17) -> 1216.1 | D20: =SUM(D7,D10,D17) -> 1391.5 | E20: =SUM(E7,E10,E17) -> 1668.3 | F20: =SUM(F7,F10,F17) -> 1692.1 | G20: =SUM(G7,G10,G17) -> 1406.4 | H20: =SUM(H7,H12,H14,H17) -> 1345.5776 | I20: =SUM(I7,I12,I17) -> 1251.7342 | J20: =SUM(J7,J12,J17) -> 1300.1628 | K20: =SUM(K7,K12,K17) -> 1357.9229 | L20: =SUM(L7,L12,L17) -> 1417.8112
B21: year over year growth | D21: =ROUND((D20-C20)/C20, 4) -> 0.1442 | E21: =ROUND((E20-D20)/D20, 4) -> 0.1989 | F21: =ROUND((F20-E20)/E20, 4) -> 0.0143 | G21: =ROUND((G20-F20)/F20, 4) -> -0.1688 | H21: =ROUND((H20-G20)/G20, 4) -> -0.0432 | I21: =ROUND((I20-H20)/H20, 4) -> -0.0697 | J21: =ROUND((J20-I20)/I20, 4) -> 0.0387 | K21: =ROUND((K20-J20)/J20, 4) -> 0.0444 | L21: =ROUND((L20-K20)/K20, 4) -> 0.0441
B23: Cost of Sales | C23: 750.6 | D23: 878.7 | E23: 1098.2 | F23: 1220.2 | G23: 951.7 | H23: =H20*H24 -> 858.47853 | I23: =I20*I24 -> 787.3408 | J23: =J20*J24 -> 812.60177 | K23: =K20*K24 -> 841.91222 | L23: =L20*L24 -> 879.04295
B24: Cost of Sales as a % of Total Sales | C24: 0.6172 | D24: 0.6315 | E24: 0.6583 | F24: 0.7211 | G24: 0.6767 | H24: 0.638 | I24: 0.629 | J24: 0.625 | K24: 0.62 | L24: 0.62
B25: year over year growth | D25: =ROUND((D23-C23)/C23, 4) -> 0.1707 | E25: =ROUND((E23-D23)/D23, 4) -> 0.2498 | F25: =ROUND((F23-E23)/E23, 4) -> 0.1111 | G25: =ROUND((G23-F23)/F23, 4) -> -0.22 | H25: =ROUND((H23-G23)/G23, 4) -> -0.098 | I25: =ROUND((I23-H23)/H23, 4) -> -0.0829 | J25: =ROUND((J23-I23)/I23, 4) -> 0.0321 | K25: =ROUND((K23-J23)/J23, 4) -> 0.0361 | L25: =ROUND((L23-K23)/K23, 4) -> 0.0441
B27: Gross Profit | C27: =C20-C23 -> 465.5 | D27: =D20-D23 -> 512.8 | E27: =E20-E23 -> 570.1 | F27: =F20-F23 -> 471.9 | G27: =G20-G23 -> 454.7 | H27: =H20-H23 -> 487.09911 | I27: =I20-I23 -> 464.39338 | J27: =J20-J23 -> 487.56106 | ... L27: =L20-L23 -> 538.76826
B28: Gross Profit Margin | C28: =C27/C20 -> 0.38278102 | D28: =D27/D20 -> 0.36852318 | E28: =E27/E20 -> 0.34172511 | F28: =F27/F20 -> 0.27888423 | G28: =G27/G20 -> 0.32330774 | H28: =H27/H20 -> 0.362 | I28: =I27/I20 -> 0.371 | J28: =J27/J20 -> 0.375 | ... L28: =L27/L20 -> 0.38

Sheet Income Statement
B3: Income Statement
B7: Fiscal Year | C7: 2020 | D7: 2021 | E7: 2022 | F7: 2023 | G7: 2024 | H7: 2025 | I7: 2026 | J7: 2027 | K7: 2028 | L7: 2029 | M7: Avg.
B8: Net Sales | C8: 1216.1 | D8: 1391.5 | E8: 1668.3 | F8: 1692.1 | G8: 1406.4 | H8: 1345.5776 | I8: 1251.7342 | J8: 1300.1628 | K8: 1357.9229 | L8: 1417.8112
B9: Costs and Expenses
B10: Cost of Sales | C10: 750.6 | D10: 878.7 | E10: 1098.2 | F10: 1220.2 | G10: 951.7 | H10: =H8*H11 -> 888.08124 | I10: =I8*I11 -> 794.8512 | J10: =J8*J11 -> 812.60177 | K10: =K8*K11 -> 835.1226 | L10: =L8*L11 -> 857.77578
B11: % of Revenue | C11: =C10/C8 -> 0.61721898 | D11: =D10/D8 -> 0.63147682 | E11: =E10/E8 -> 0.65827489 | F11: =F10/F8 -> 0.72111577 | G11: =G10/G8 -> 0.67669226 | H11: 0.66 | I11: 0.635 | J11: 0.625 | K11: 0.615 | L11: 0.605
B12: Gross Profit | C12: 149.4 | D12: 179.3 | E12: 198.8 | F12: 183.7 | G12: 166.7 | H12: =H8-H10 -> 457.4964 | I12: =I8-I10 -> 456.88298 | J12: =J8-J10 -> 487.56106 | K12: =K8-K10 -> 522.80033 | L12: =L8-L10 -> 560.03543
B14: Selling, general, and administrative | C14: 149.4 | D14: 179.3 | E14: 198.8 | F14: 183.7 | G14: 166.7 | H14: =H8*H56 -> 152.05027 | I14: =I8*I56 -> 137.69076 | J14: =J8*J56 -> 140.41759 | K14: =K8*K56 -> 145.29775 | L14: =L8*L56 -> 148.87018
B15: Research and technical expenses | C15: 22.6 | D15: 26.3 | E15: 30.3 | F15: 31.8 | G15: 28.1 | H15: =H8*H57 -> 26.911553 | I15: =I8*I57 -> 25.660551 | J15: =J8*J57 -> 27.30342 | K15: =K8*K57 -> 29.195343 | L15: =L8*L57 -> 30.482941
B16: Restructing and other (income) charges | C16: 18.5 | D16: 16.2 | E16: 13.8 | F16: 170.2 | G16: 186.2 | H16: =H8*H58 -> 67.278882 | I16: =I8*I58 -> 12.517342 | J16: =J8*J58 -> 10.401303 | K16: =K8*K58 -> 8.1475376 | L16: =L8*L58 -> 7.089056
B17: Goodwill impairment charge | C17: 0 | D17: 0 | E17: 0 | F17: 0 | G17: 349.1 | H17: 0 | I17: 0 | J17: 0 | K17: 0 | L17: 0
B18: Acquisition-related costs | C18: 1.8 | D18: 0.6 | E18: 5 | F18: 3.6 | G18: 0.3 | H18: =H8*H60 -> 0.67278882 | I18: =I8*I60 -> 0.62586709 | J18: =J8*J60 -> 0.65008142 | K18: =K8*K60 -> 0.67896147 | L18: =L8*L60 -> 0.7089056
B19: Total Operating Expenses | C19: =SUM(C14:C18) -> 192.3 | D19: =SUM(D14:D18) -> 222.4 | E19: =SUM(E14:E18) -> 247.9 | F19: =SUM(F14:F18) -> 389.3 | G19: =SUM(G14:G18) -> 730.4 | H19: =H14+H15+H16+H17+H18 -> 246.9135 | I19: =I14+I15+I16+I17+I18 -> 176.49452 | J19: =J14+J15+J16+J17+J18 -> 178.77239 | K19: =K14+K15+K16+K17+K18 -> 183.3196 | L19: =L14+L15+L16+L17+L18 -> 187.15108
B21: EBIT | C21: =C12-C19 -> -42.9 | D21: =D12-D19 -> -43.1 | E21: =E12-E19 -> -49.1 | F21: =F12-F19 -> -205.6 | G21: =G12-G19 -> -563.7 | H21: =H12-H19 -> 210.5829 | I21: =I12-I19 -> 280.38846 | J21: =J12-J19 -> 308.78867 | ... L21: =L12-L19 -> 372.88435
B22: Operating Margin Percentage | C22: 0.22802401 | D22: 0.1512756 | E22: 0.19414973 | F22: 0.045446487 | G22: -0.31676621 | H22: =H21/H8 -> 0.1565 | I22: =I21/I8 -> 0.224 | J22: =J21/J8 -> 0.2375 | K22: =K21/K8 -> 0.25 | L22: =L21/L8 -> 0.263
B23: Depreciation & Amortization | C23: 100.2 | D23: 109.9 | E23: 108.8 | F23: 122.8 | G23: 108.3 | H23: =H8*$H$68 -> 101.2326 | I23: =I8*$H$68 -> 94.172421 | J23: =J8*$H$68 -> 97.815881 | K23: =K8*$H$68 -> 102.16138 | L23: =L8*$H$68 -> 106.66699
B24: EBITDA | C24: =C21+C23 -> 57.3 | D24: =D21+D23 -> 66.8 | E24: =E21+E23 -> 59.7 | F24: =F21+F23 -> -82.8 | G24: =G21+G23 -> -455.4 | H24: =H21+H23 -> 311.8155 | I24: =I21+I23 -> 374.56088 | J24: =J21+J23 -> 406.60456 | ... L24: =L21+L23 -> 479.55133
B26: Adj. EBITDA | C26: 397.9 | D26: 422.2 | E26: 452.6 | F26: 377.1 | G26: 362.7 | H26: =H24+H17+H18+H16 -> 379.76717 | I26: =I24+I17+I18+I16 -> 387.70409 | J26: =J24+J17+J18+J16 -> 417.65594 | K26: =K24+K17+K18+K16 -> 450.46861 | L26: =L24+L17+L18+L16 -> 487.3493
B28: Non-Operating Income / Expense
B29: Other (income) expense, net | C29: -4.1 | D29: 79.9 | E29: -1.7 | F29: 5.7 | G29: 169.8 | H29: 0 | I29: 0 | J29: 0 | K29: 0 | L29: 0
B30: Interest expense | C30: 47.1 | D30: 51.7 | E30: 61.8 | F30: 93.3 | G30: 97.8 | H30: =H8*$H$62 -> 63.914938 | I30: =I8*$H$62 -> 59.457374 | J30: =J8*$H$62 -> 61.757735 | K30: =K8*$H$62 -> 64.501339 | L30: =L8*$H$62 -> 67.346032
B31: Interest income | C31: 4.9 | D31: 4 | E31: 7.5 | F31: 6.3 | G31: 7.7 | H31: =H74 -> 3.8176728 | I31: =I74 -> 12.060613 | J31: =J74 -> 14.706156 | K31: =K74 -> 14.635437 | L31: =L74 -> 14.724545
B32: Total Non-Operating Income | C32: =C29-C30+C31 -> -46.3 | D32: =D29-D30+D31 -> 32.2 | E32: =E29-E30+E31 -> -56 | F32: =F29-F30+F31 -> -81.3 | G32: =G29-G30+G31 -> 79.7 | H32: =H29-H30+H31 -> -60.097265 | I32: =I29-I30+I31 -> -47.39676 | J32: =J29-J30+J31 -> -47.051578 | ... L32: =L29-L30+L31 -> -52.621487
B34: Income (Loss) Before Income Taxes | C34: =C21+C32 -> -89.2 | D34: =D21+D32 -> -10.9 | E34: =E21+E32 -> -105.1 | F34: =F21+F32 -> -286.9 | G34: =G21+G32 -> -484 | H34: =H21+H32 -> 150.48564 | I34: =I21+I32 -> 232.9917 | J34: =J21+J32 -> 261.7371 | ... L34: =L21+L32 -> 320.26286
B36: Taxes | C36: 235.1 | D36: 162.8 | E36: 269.6 | F36: -10.1 | G36: -535.6 | H36: =H21*$M$45 -> 58.120881 | I36: =I21*$M$45 -> 77.387214 | J36: =J21*$M$45 -> 85.225674 | K36: =K21*$M$45 -> 93.696682 | L36: =L21*$M$45 -> 102.91608
B37: Provision (benefit) for income taxes | C37: 53.7 | D37: 44.7 | E37: 58 | F37: -4.7 | G37: -105.3 | H37: =H34*$M$45 -> 41.534035 | I37: =I34*$M$45 -> 64.305708 | J37: =J34*$M$45 -> 72.239438 | K37: =K34*$M$45 -> 79.933693 | L37: =L34*$M$45 -> 88.392549
B39: Net Income (loss) | C39: 181.4 | D39: 118.1 | E39: 211.6 | F39: -5.4 | G39: -430.3 | H39: =H34-H37 -> 108.9516 | I39: =I34-I37 -> 168.68599 | J39: =J34-J37 -> 189.49766 | K39: =K34-K37 -> 209.68114 | L39: =L34-L37 -> 231.87031
B41: Basic EPS | C41: 4.39 | D41: 2.97 | E41: 5.54 | F41: -0.15 | G41: -11.85 | H41: =H39/(H43/1000) -> 2.999521 | I41: =I39/(I43/1000) -> 4.6440544 | J41: =J39/(J43/1000) -> 5.2170156 | K41: =K39/(K43/1000) -> 5.7726823 | L41: =L39/(L43/1000) -> 6.3835672
B42: Diluted EPS | C42: 4.37 | D42: 2.95 | E42: 5.5 | F42: -0.15 | G42: -11.85 | H42: =H39/(H43/1000) -> 2.999521 | I42: =I39/(I43/1000) -> 4.6440544 | J42: =J39/(J43/1000) -> 5.2170156 | K42: =K39/(K43/1000) -> 5.7726823 | L42: =L39/(L43/1000) -> 6.3835672
B43: Weighted Average Shares Outstanding | C43: 41547 | D43: 40059 | E43: 38471 | F43: 36496 | G43: 36323 | H43: 36323 | I43: 36323 | J43: 36323 | K43: 36323 | L43: 36323
B45: Effectuve Tax Rate | C45: 0.228 | D45: 0.275 | E45: 0.215 | F45: 0.465 | G45: 0.197 | M45: =AVERAGE(C45:G45) -> 0.276
B52: Fiscal Year | C52: 2020 | D52: 2021 | E52: 2022 | F52: 2023 | G52: 2024 | H52: 2025 | I52: 2026 | J52: 2027 | K52: 2028 | L52: 2029
B53: Net Sales | C53: 1 | D53: 1 | E53: 1 | F53: 1 | G53: 1
B54: Cost of Sales | C54: 0.6172 | D54: 0.6315 | E54: 0.6583 | F54: 0.7211 | G54: 0.6767
B55: Gross Profit | C55: 0.3828 | D55: 0.3685 | E55: 0.3417 | F55: 0.2789 | G55: 0.3233
B56: Selling, general, and administrative | C56: 0.1229 | D56: 0.1289 | E56: 0.1192 | F56: 0.1086 | G56: 0.1185 | H56: 0.113 | I56: 0.11 | J56: 0.108 | K56: 0.107 | L56: 0.105
B57: Research and technical expenses | C57: 0.0186 | D57: 0.0189 | E57: 0.0182 | F57: 0.0188 | G57: 0.02 | H57: 0.02 | I57: 0.0205 | J57: 0.021 | K57: 0.0215 | L57: 0.0215
B58: Restructing and other (income) charges | C58: 0.0152 | D58: 0.0116 | E58: 0.0083 | F58: 0.1006 | G58: 0.1324 | H58: 0.05 | I58: 0.01 | J58: 0.008 | K58: 0.006 | L58: 0.005
B59: Goodwill impairment charge | C59: 0 | D59: 0 | E59: 0 | F59: 0 | G59: 0.2482
B60: Acquisition-related costs | C60: 0.0015 | D60: 0.0004 | E60: 0.003 | F60: 0.0021 | G60: 0.0002 | H60: 0.0005 | I60: 0.0005 | J60: 0.0005 | K60: 0.0005 | L60: 0.0005
...

Sheet Balance Sheet
B4: Balance Sheet
B8: Fiscal Year | C8: 2020 | D8: 2021 | E8: 2022 | F8: 2023 | G8: 2024 | H8: 2025 | I8: 2026 | J8: 2027 | K8: 2028 | L8: 2029
B9: Assets
B10: Current Assets
B11: Cash and Cash Equivalents | C11: 257.7 | D11: 275.4 | E11: 76.7 | F11: 95.9 | G11: 68 | H11: ='Cash Flow'!H68 -> 182.2968 | I11: ='Cash Flow'!I68 -> 174.96879 | J11: ='Cash Flow'!J68 -> 231.09915 | K11: ='Cash Flow'!K68 -> 293.22026 | L11: ='Cash Flow'!L68 -> 358.72574
B12: Accounts Receivable, net | C12: 148 | D12: 161.7 | E12: 224.8 | F12: 182 | G12: 141 | H12: =42.73*(H68/365) -> 157.52475 | I12: =42.73*(I68/365) -> 146.53863 | J12: =42.73*(J68/365) -> 152.2081 | K12: =42.73*(K68/365) -> 158.96999 | L12: =42.73*(L68/365) -> 165.98102
B13: Inventories | C13: 189 | D13: 241.2 | E13: 335 | F13: 308.8 | G13: 226.8 | H13: =$H$76*(H70/365) -> 234.68216 | I13: =$H$76*(I70/365) -> 210.04542 | J13: =$H$76*(J70/365) -> 214.73614 | K13: =$H$76*(K70/365) -> 220.68744 | L13: =$H$76*(L70/365) -> 226.67371
B14: Prepayments and other current assets | C14: 34 | D14: 46.6 | E14: 46.8 | F14: 71.9 | G14: 57.4 | H14: 57.4 | I14: 57.4 | J14: 57.4 | K14: 57.4 | L14: 57.4
B15: Total Current Assets | C15: =SUM(C11:C14) -> 628.7 | D15: =SUM(D11:D14) -> 724.9 | E15: =SUM(E11:E14) -> 683.3 | F15: =SUM(F11:F14) -> 658.6 | G15: =SUM(G11:G14) -> 493.2 | H15: =SUM(H11:H14) -> 631.90371 | I15: =SUM(I11:I14) -> 588.95284 | J15: =SUM(J11:J14) -> 655.44339 | ... L15: =SUM(L11:L14) -> 808.78047
B17: Long-term/Non-Current Assets
B18: Property, plant, and equipment, net | C18: 703.6 | D18: 719.7 | E18: 798.6 | F18: 762.2 | G18: 658.9 | H18: =G18+'Cash Flow'!H40-'Cash Flow'!H11 -> 624.94628 | I18: =H18+'Cash Flow'!I40-'Cash Flow'!I11 -> 593.36057 | J18: =I18+'Cash Flow'!J40-'Cash Flow'!J11 -> 560.55283 | K18: =J18+'Cash Flow'!K40-'Cash Flow'!K11 -> 526.2876 | L18: =K18+'Cash Flow'!L40-'Cash Flow'!L11 -> 490.51117
B19: Operating lease assets | C19: 49.1 | D19: 52.4 | E19: 56.6 | F19: 67.1 | G19: 50.4 | H19: =G19*(1-0.05) -> 47.88 | I19: =H19*(1-0.05) -> 45.486 | J19: =I19*(1-0.05) -> 43.2117 | K19: =J19*(1-0.05) -> 41.051115 | L19: =K19*(1-0.05) -> 38.998559
B20: Goodwill | C20: 445.3 | D20: 442 | E20: 518.5 | F20: 527.5 | G20: 175.2 | H20: 175.2 | I20: 175.2 | J20: 175.2 | K20: 175.2 | L20: 175.2
B21: Intangible assets | C21: 373.3 | D21: 337.3 | E21: 404.8 | F21: 336.1 | G21: 278.8 | H21: =G21-$C$95 -> 302.425 | I21: =H21-$C$95 -> 326.05 | J21: =I21-$C$95 -> 349.675 | K21: =J21-$C$95 -> 373.3 | L21: =K21-$C$95 -> 396.925
B22: Intangibles amortization | D22: =D21-C21 -> -36 | E22: =E21-D21 -> 67.5 | F22: =F21-E21 -> -68.7 | G22: =G21-F21 -> -57.3 | H22: =H21-G21 -> 23.625 | I22: =I21-H21 -> 23.625 | J22: =J21-I21 -> 23.625 | K22: =K21-J21 -> 23.625 | L22: =L21-K21 -> 23.625
B23: Deferred income taxes | C23: 8.1 | D23: 6.8 | E23: 5.7 | F23: 11.6 | G23: 117.9 | H23: =(C23+D23+E23+F23)/4 -> 8.05 | I23: 8.1 | J23: 8.1 | K23: 8.1 | L23: 8.1
B24: Strategic Investments | C24: 0 | D24: 0 | E24: 109.8 | F24: 99.2 | G24: 87.3 | H24: =G24*(1-0.05) -> 82.935 | I24: =H24*(1-0.05) -> 78.78825 | J24: =I24*(1-0.05) -> 74.848837 | K24: =J24*(1-0.05) -> 71.106396 | L24: =K24*(1-0.05) -> 67.551076
B25: Other assets | C25: =73.6+52.8 -> 126.4 | D25: =76.1+109.5 -> 185.6 | E25: =78+81.2 -> 159.2 | F25: =79.1+81.9 -> 161 | G25: =81.6+79.3 -> 160.9 | H25: =81.6+79.3 -> 160.9 | I25: =81.6+79.3 -> 160.9 | J25: =81.6+79.3 -> 160.9 | K25: =81.6+79.3 -> 160.9 | L25: =81.6+79.3 -> 160.9
B26: Total non-current assets | C26: =C18+C19+C20+C21+C23+C24+C25 -> 1705.8 | D26: =D18+D19+D20+D21+D23+D24+D25 -> 1743.8 | E26: =E18+E19+E20+E21+E23+E24+E25 -> 2053.2 | F26: =F18+F19+F20+F21+F23+F24+F25 -> 1964.7 | G26: =G18+G19+G20+G21+G23+G24+G25 -> 1529.4 | H26: =H18+H19+H20+H21+H23+H24+H25 -> 1402.3363 | I26: =I18+I19+I20+I21+I23+I24+I25 -> 1387.8848 | J26: =J18+J19+J20+J21+J23+J24+J25 -> 1372.4884 | ... L26: =L18+L19+L20+L21+L23+L24+L25 -> 1338.1858
B28: Total Assets | C28: =C15+C26 -> 2334.5 | D28: =D15+D26 -> 2468.7 | E28: =E15+E26 -> 2736.5 | F28: =F15+F26 -> 2623.3 | G28: =G15+G26 -> 2022.6 | H28: =H15+H26 -> 2034.24 | I28: =I15+I26 -> 1976.8377 | J28: =J15+J26 -> 2027.9318 | ... L28: =L15+L26 -> 2146.9663
B30: Liabilites and Equity
B31: Current Liabilites
B32: Accounts payable | C32: 104.2 | D32: 125.8 | E32: 174.8 | F32: 158.4 | G32: 94.5 | H32: =$H$77*(H70/365) -> 119.91287 | I32: =$H$77*(I70/365) -> 107.32451 | J32: =$H$77*(J70/365) -> 109.72128 | K32: =$H$77*(K70/365) -> 112.76214 | L32: =$H$77*(L70/365) -> 115.82088
B33: Accrued expenses | C33: 46.6 | D33: 51.7 | E33: 54.4 | F33: 72.3 | G33: 58.1 | H33: =$H$82*H80 -> 47.382723 | I33: =$H$82*I80 -> 33.869314 | J33: =$H$82*J80 -> 34.306438 | K33: =$H$82*K80 -> 35.179047 | L33: =$H$82*L80 -> 35.914309
B34: Accrued payroll and employee benefits | C34: 25.1 | D34: 48.2 | E34: 53.3 | F34: 19.9 | G34: 27.7 | H34: =$C$86*H85 -> 32.228439 | I34: =$C$86*I85 -> 23.036986 | J34: =$C$86*J85 -> 23.334306 | K34: =$C$86*K85 -> 23.927831 | L34: =$C$86*L85 -> 24.427936
B35: Current operating lease liabilites | C35: 16.2 | D35: 17.4 | E35: 16.5 | F35: 18.7 | G35: 16.9 | H35: 15.86 | I35: 15.555 | J35: 15.25 | K35: 14.945 | L35: 14.64
B36: Notes Payable and current maturities of long-term debt | C36: 26 | D36: 19.6 | E36: 0.9 | F36: 84.4 | G36: 61.3 | H36: 61.3 | I36: 61.3 | J36: 61.3 | K36: 61.3 | L36: 61.3
B37: Income taxes payable | C37: 5.3 | D37: 6.2 | E37: 3.6 | F37: 9.2 | G37: 5.6 | H37: 5.6 | I37: 5.6 | J37: 5.6 | K37: 5.6 | L37: 5.6
B38: Total short-term liabilites | C38: =SUM(C32:C37) -> 223.4 | D38: =SUM(D32:D37) -> 268.9 | E38: =SUM(E32:E37) -> 303.5 | F38: =SUM(F32:F37) -> 362.9 | G38: =SUM(G32:G37) -> 264.1 | H38: =SUM(H32:H37) -> 282.28403 | I38: =SUM(I32:I37) -> 246.68581 | J38: =SUM(J32:J37) -> 249.51202 | ... L38: =SUM(L32:L37) -> 257.70313
B40: Long-Term Liabilities
B41: Long-term debt including finance lease obligations | C41: 1267.4 | D41: 1250 | E41: 1472.5 | F41: 1382.8 | G41: 1339.7 | H41: 1339.7 | I41: 1339.7 | J41: 1339.7 | K41: 1339.7 | L41: 1339.7
B42: Noncurrent operating lease liabilities | C42: 34.7 | D42: 36.2 | E42: 40.8 | F42: 48.6 | G42: 36.8 | H42: =AVERAGE(C42:G42) -> 39.42 | I42: 39.4 | J42: 39.4 | K42: 39.4 | L42: 39.4
B43: Deferred income taxes | C43: 117 | D43: 114.6 | E43: 106.5 | F43: 70.9 | G43: 56.2 | H43: 56.2 | I43: 56.2 | J43: 56.2 | K43: 56.2 | L43: 56.2
B44: Other liabilites | C44: 49.9 | D44: 125.5 | E44: 114.9 | F44: 126.7 | G44: 130.6 | H44: =AVERAGE(D44:G44) -> 124.425 | I44: 124.4 | J44: 124.4 | K44: 124.4 | L44: 124.4
B45: Total Long-Term Liabilities | C45: =SUM(C41:C44) -> 1469 | D45: =SUM(D41:D44) -> 1526.3 | E45: =SUM(E41:E44) -> 1734.7 | F45: =SUM(F41:F44) -> 1629 | G45: =SUM(G41:G44) -> 1563.3 | H45: =SUM(H41:H44) -> 1559.745 | I45: =SUM(I41:I44) -> 1559.7 | J45: =SUM(J41:J44) -> 1559.7 | ... L45: =SUM(L41:L44) -> 1559.7
B47: Total Liabilities | C47: =C38+C45 -> 1692.4 | D47: =D38+D45 -> 1795.2 | E47: =E38+E45 -> 2038.2 | F47: =F38+F45 -> 1991.9 | G47: =G38+G45 -> 1827.4 | H47: =H38+H45 -> 1842.029 | I47: =I38+I45 -> 1806.3858 | J47: =J38+J45 -> 1809.212 | ... L47: =L38+L45 -> 1817.4031
B49: Shareholders' Equity
B50: Common Stock | C50: 0.4 | D50: 0.4 | E50: 0.4 | F50: 0.4 | G50: 0.4 | H50: 0.4 | I50: 0.4 | J50: 0.4 | K50: 0.4 | L50: 0.4
B51: Additional Paid-in Capital | C51: 121.3 | D51: 136.3 | E51: 153 | F51: 164.9 | G51: 176.8 | H51: =G51+$M$96 -> 190.675 | I51: =H51+$M$96 -> 204.55 | J51: =I51+$M$96 -> 218.425 | K51: =J51+$M$96 -> 232.3 | L51: =K51+$M$96 -> 246.175
B52: Retained Earnings | C52: 678 | D52: 796.1 | E52: 1007.7 | F52: 1002.3 | G52: 572 | H52: =G52+'Income Statement'!H39 -> 680.9516 | I52: =H52+'Income Statement'!I39 -> 849.63759 | J52: =I52+'Income Statement'!J39 -> 1039.1352 | K52: =J52+'Income Statement'!K39 -> 1248.8164 | L52: =K52+'Income Statement'!L39 -> 1480.6867
...

Sheet Cash Flow
B3: Statement of Cash Flows
B6: Fiscal Year | C6: 2020 | D6: 2021 | E6: 2022 | F6: 2023 | G6: 2024 | H6: 2025 | I6: 2026 | J6: 2027 | K6: 2028 | L6: 2029
B7: Cash Flow from Operating Activities
B8: Net Income | C8: 181.4 | D8: 118.1 | E8: 211.6 | F8: -5.4 | G8: -430.3 | H8: 108.9516 | I8: 168.68599 | J8: 189.49766 | K8: 209.68114 | L8: 231.87031
B10: Adjustments to reconcile net income (loss) to cash provided by operating activities
B11: Depreciation and Amortization | C11: 100.2 | D11: 109.9 | E11: 108.8 | F11: 122.8 | G11: 108.3 | H11: 101.2326 | I11: 94.172421 | J11: 97.815881 | K11: 102.16138 | L11: 106.66699
B12: Non Cash Operating lease costs | C12: 18 | D12: 17.3 | E12: 16.1 | F12: 18.6 | G12: 19.1 | H12: 19.1 | I12: 19.1 | J12: 19.1 | K12: 19.1 | L12: 19.1
B13: Deferred Income taxes | C13: 16.2 | D13: -4.6 | E13: -5 | F13: -44.7 | G13: -121.4 | H13: 0 | I13: 0 | J13: 0 | K13: 0 | L13: 0
B14: Disposal/Impairment of assets | C14: 0.6 | D14: 1.2 | E14: 2.5 | F14: 4.3 | G14: 1.3 | H14: 0 | I14: 0 | J14: 0 | K14: 0 | L14: 0
B15: Restructuring and other (income) charges, net | C15: 1.7 | D15: 0 | E15: 13.8 | F15: 170.2 | G15: 186.2 | H15: 15 | I15: 1 | J15: 1 | K15: 1 | L15: 1
B16: CTO resales | C16: 0 | D16: 0 | E16: 0 | F16: 22 | G16: 52.7 | H16: 0 | I16: 0 | J16: 0 | K16: 0 | L16: 0
B17: LIFO reserve | C17: 3.9 | D17: 3.5 | E17: 10 | F17: 72.9 | G17: -18.7 | H17: 0 | I17: 0 | J17: 0 | K17: 0 | L17: 0
B18: Share-Based Compensation | C18: 8.4 | D18: 12.3 | E18: 16.1 | F18: 10.6 | G18: 11.9 | H18: =$M$77*H76 -> 10.797716 | I18: =$M$77*I76 -> 10.04466 | J18: =$M$77*J76 -> 10.43328 | K18: =$M$77*K76 -> 10.896782 | L18: =$M$77*L76 -> 11.377361
B19: (Gain) Loss on strategic investment | C19: 0 | D19: 0 | E19: 0 | F19: -19.3 | G19: 11.4 | H19: 0 | I19: 0 | J19: 0 | K19: 0 | L19: 0
B20: Pension and other postretirement benefit costs | C20: 1.9 | D20: 1.6 | E20: 1.4 | F20: 1.6 | G20: 1.5 | H20: 1.5 | I20: 1.5 | J20: 1.5 | K20: 1.5 | L20: 1.5
B21: Goodwill impairment charge | C21: 0 | D21: 0 | E21: 0 | F21: 0 | G21: 349.1 | H21: 0 | I21: 0 | J21: 0 | K21: 0 | L21: 0
B22: Other non-cash items | C22: 15.3 | D22: 12.1 | E22: 17 | F22: 36.2 | G22: 17 | H22: 17 | I22: 17 | J22: 17 | K22: 17 | L22: 17
B24: Changes in operating assets and liabilities, net of effect of acquisitions
B25: Accounts receivable, net | C25: 2.8 | D25: -13.8 | E25: -42.1 | F25: 42.7 | G25: 38.2 | H25: ='Balance Sheet'!H12-'Balance Sheet'!G12 -> 16.524747 | I25: ='Balance Sheet'!I12-'Balance Sheet'!H12 -> -10.986112 | J25: ='Balance Sheet'!J12-'Balance Sheet'!I12 -> 5.66947 | K25: ='Balance Sheet'!K12-'Balance Sheet'!J12 -> 6.7618873 | L25: ='Balance Sheet'!L12-'Balance Sheet'!K12 -> 7.0110298
B26: Inventories, net | C26: 22.3 | D26: -55.8 | E26: -63.7 | F26: -75.6 | G26: 86.2 | H26: ='Balance Sheet'!H13-'Balance Sheet'!G13 -> 7.8821592 | I26: ='Balance Sheet'!I13-'Balance Sheet'!H13 -> -24.63674 | J26: ='Balance Sheet'!J13-'Balance Sheet'!I13 -> 4.6907217 | K26: ='Balance Sheet'!K13-'Balance Sheet'!J13 -> 5.9512991 | L26: ='Balance Sheet'!L13-'Balance Sheet'!K13 -> 5.9862723
B27: Prepaid and other current assets | C27: 2.1 | D27: -5.9 | E27: -0.8 | F27: -28.6 | G27: 7.7 | H27: ='Balance Sheet'!H14-'Balance Sheet'!G14 -> 0 | I27: ='Balance Sheet'!I14-'Balance Sheet'!H14 -> 0 | J27: ='Balance Sheet'!J14-'Balance Sheet'!I14 -> 0 | K27: ='Balance Sheet'!K14-'Balance Sheet'!J14 -> 0 | L27: ='Balance Sheet'!L14-'Balance Sheet'!K14 -> 0
B28: Planned major maintenance outage | C28: -7 | D28: -8.6 | E28: -9.1 | F28: -12.8 | G28: -6.5 | H28: =AVERAGE(C28:G28) -> -8.8 | I28: -8.8 | J28: -8.8 | K28: -8.8 | L28: -8.8
B29: Accounts payable | C29: 9.4 | D29: 14.8 | E29: 42.7 | F29: -14.6 | G29: -63.4 | H29: ='Balance Sheet'!H32-'Balance Sheet'!G32 -> 25.412866 | I29: ='Balance Sheet'!I32-'Balance Sheet'!H32 -> -12.588354 | J29: ='Balance Sheet'!J32-'Balance Sheet'!I32 -> 2.3967646 | K29: ='Balance Sheet'!K32-'Balance Sheet'!J32 -> 3.0408674 | L29: ='Balance Sheet'!L32-'Balance Sheet'!K32 -> 3.0587373
B30: Accrued expenses | C30: 13.4 | D30: 4.8 | E30: 0.8 | F30: -7.7 | G30: -1 | H30: =$M$79*'Income Statement'!H14 -> 2.2069201 | I30: =$M$79*'Income Statement'!I14 -> 1.9985003 | J30: =$M$79*'Income Statement'!J14 -> 2.0380785 | K30: =$M$79*'Income Statement'!K14 -> 2.1089113 | L30: =$M$79*'Income Statement'!L14 -> 2.1607629
B31: Accrued payroll and employee benefits | C31: -3.3 | D31: 23.1 | E31: 5.4 | F31: -33.5 | G31: 8 | H31: =$M$80*H76 -> 0.81122821 | I31: =$M$80*I76 -> 0.75465142 | J31: =$M$80*J76 -> 0.78384832 | K31: =$M$80*K76 -> 0.818671 | L31: =$M$80*L76 -> 0.85477672
B32: Income taxes | C32: -9.6 | D32: -6.2 | E32: 4.9 | F32: 6.4 | G32: -13.8 | H32: =AVERAGE(C32:G32) -> -3.66 | I32: -3.7 | J32: -3.7 | K32: -3.7 | L32: -3.7
B33: Operating leases | C33: -18.5 | D33: -20.5 | E33: -18.8 | F33: -22.5 | G33: -21.7 | H33: =AVERAGE(C33:G33) -> -20.4 | I33: -20.4 | J33: -20.4 | K33: -20.4 | L33: -20.4
B34: Restructuring and other spending | C34: 0 | D34: 0 | E34: -13.8 | F34: -44 | G34: -59.3 | H34: 0 | I34: 0 | J34: 0 | K34: 0 | L34: 0
B35: CTO resales | C35: 0 | D35: 0 | E35: 0 | F35: -10.6 | G35: -46.1 | H35: 0 | I35: 0 | J35: 0 | K35: 0 | L35: 0
B36: Changes in all other operating assets and liabilies, net. | C36: -6.8 | D36: 4.7 | E36: 14.2 | F36: 16.1 | G36: 12.2 | H36: =AVERAGE(C36:G36) -> 8.08 | I36: 8.08 | J36: 8.08 | K36: 8.08 | L36: 8.08
B37: Net cash provided by (used in) operating activities | C37: 352.4 | D37: 293 | E37: 313.4 | F37: 205.1 | G37: 128.6 | H37: =SUM(H25:H36) -> 28.05792 | I37: =SUM(I25:I36) -> -70.278054 | J37: =SUM(J25:J36) -> -9.2411168 | K37: =SUM(K25:K36) -> -6.1383639 | L37: =SUM(L25:L36) -> -5.748421
B39: Cash provided by (used in) investing activities:
B40: Capital expeditures | C40: 82.1 | D40: 103.8 | E40: 142.5 | F40: 109.8 | G40: 77.6 | H40: =H41*H76 -> 67.278882 | I40: =I41*I76 -> 62.586709 | J40: =J41*J76 -> 65.008142 | K40: =K41*K76 -> 67.896147 | L40: =L41*L76 -> 70.89056
B41: CapEx as a % of Revenue | C41: =C40/C76 -> 0.067510895 | D41: =D40/D76 -> 0.07459576 | E41: =E40/E76 -> 0.085416292 | F41: =F40/F76 -> 0.064889782 | G41: =G40/G76 -> 0.055176337 | H41: 0.05 | I41: 0.05 | J41: 0.05 | K41: 0.05 | L41: 0.05
B42: Payments for acquired businesses, net of cash acquired | C42: -23.8 | D42: 0 | E42: -344.5 | F42: 0 | G42: 0 | H42: 0 | I42: 0 | J42: 0 | K42: 0 | L42: 0
B43: Proceeds from sale of strategic investment | C43: 0 | D43: 0 | E43: 0 | F43: 31.5 | G43: 0 | H43: 0 | I43: 0 | J43: 0 | K43: 0 | L43: 0
B44: Net investment hedge settlement | C44: 0 | D44: 0 | E44: 14.7 | F44: 0 | G44: 0 | H44: 0 | I44: 0 | J44: 0 | K44: 0 | L44: 0
B45: Purchase of strategic investments | C45: 0 | D45: -35.3 | E45: -77.4 | F45: -2.4 | G45: -0.3 | H45: 0 | I45: 0 | J45: 0 | K45: 0 | L45: 0
B46: Other investing activities, net | C46: -4.7 | D46: -1.5 | E46: -2.2 | F46: 3.4 | G46: -1.6 | H46: =(E46+F46+G46)/3 -> -0.13333333 | I46: -0.13 | J46: -0.13 | K46: -0.13 | L46: -0.13
B47: Net cash provided by (used in) investing activities | C47: -110.6 | D47: -140.6 | E47: 313.4 | F47: 205.1 | G47: 128.6 | H47: =H40+H46 -> 67.145549 | I47: =I40+I46 -> 62.456709 | J47: =J40+J46 -> 64.878142 | K47: =K40+K46 -> 67.766147 | L47: =L40+L46 -> 70.76056
...

Sheet Beta
A1: Beta
A2: NGVT | D2: SPY | G2: Beta
A3: {=_xlfn.STOCKHISTORY("NGVT", DATE(2020,1,1), DATE(2024,12,31),1)} -> Date | B3: Close | C3: NGVT Return | D3: {=_xlfn.STOCKHISTORY("SPY", DATE(2020,1,1), DATE(2024,12,31),1,)} -> Date | E3: Close | F3: SPY Return | G3: =SLOPE(C5:C265,F5:F265) -> 1.4629793
A4: 43829 | B4: 84.44 | D4: 43829 | E4: 322.41
A5: 43836 | B5: 78.96 | C5: =(B5/B4)-1 -> -0.064898153 | D5: 43836 | E5: 325.71 | F5: =(E5/E4)-1 -> 0.010235415
A6: 43843 | B6: 82.56 | C6: =(B6/B5)-1 -> 0.045592705 | D6: 43843 | E6: 331.95 | F6: =(E6/E5)-1 -> 0.019158147
A7: 43851 | B7: 77.88 | C7: =(B7/B6)-1 -> -0.056686047 | D7: 43851 | E7: 328.77 | F7: =(E7/E6)-1 -> -0.009579756
A8: 43857 | B8: 65.22 | C8: =(B8/B7)-1 -> -0.16255778 | D8: 43857 | E8: 321.73 | F8: =(E8/E7)-1 -> -0.021413146
A9: 43864 | B9: 66.84 | C9: =(B9/B8)-1 -> 0.024839006 | D9: 43864 | E9: 332.2 | F9: =(E9/E8)-1 -> 0.032542815
A10: 43871 | B10: 66.84 | C10: =(B10/B9)-1 -> 0 | D10: 43871 | E10: 337.6 | F10: =(E10/E9)-1 -> 0.016255268
A11: 43879 | B11: 58.49 | C11: =(B11/B10)-1 -> -0.12492519 | D11: 43879 | E11: 333.48 | F11: =(E11/E10)-1 -> -0.012203791
A12: 43885 | B12: 45.04 | C12: =(B12/B11)-1 -> -0.22995384 | D12: 43885 | E12: 296.26 | F12: =(E12/E11)-1 -> -0.11161089
A13: 43892 | B13: 46.89 | C13: =(B13/B12)-1 -> 0.0410746 | D13: 43892 | E13: 297.46 | F13: =(E13/E12)-1 -> 0.0040504962
A14: 43899 | B14: 37.83 | C14: =(B14/B13)-1 -> -0.19321817 | D14: 43899 | E14: 269.32 | F14: =(E14/E13)-1 -> -0.094600955
A15: 43906 | B15: 28.16 | C15: =(B15/B14)-1 -> -0.25561723 | D15: 43906 | E15: 228.8 | F15: =(E15/E14)-1 -> -0.15045299
A16: 43913 | B16: 33.47 | C16: =(B16/B15)-1 -> 0.18856534 | D16: 43913 | E16: 253.42 | F16: =(E16/E15)-1 -> 0.1076049
... A265: 45656 | B265: 39.86 | C265: =(B265/B264)-1 -> -0.018226601 | D265: 45656 | E265: 591.95 | F265: =(E265/E264)-1 -> -0.0051427707

Sheet DCF
B4: DCF Model
B8: Year | C8: 2025 | D8: 2026 | E8: 2027 | F8: 2028 | G8: 2029 | J8: WACC:
B10: Revenue | C10: 1345.5776 | D10: 1251.7342 | E10: 1300.1628 | F10: 1357.9229 | G10: 1417.8112 | J10: Risk-Free | K10: 0.0364
B11: Chg. YoY in % | D11: =(D10-C10)/C10 -> -0.069742136 | E11: =(E10-D10)/D10 -> 0.038689251 | F11: =(F10-E10)/E10 -> 0.044425278 | G11: =(G10-F10)/F10 -> 0.044102851 | J11: Beta | K11: 1.4629793
B12: NOPAT | C12: =C48*(1-C49) -> 152.46202 | D12: =D48*(1-D49) -> 280.38846 | E12: =E48*(1-E49) -> 308.78867 | F12: =F48*(1-F49) -> 339.48073 | G12: =G48*(1-G49) -> 372.88435 | J12: Equity Risk Premium | K12: 0.055
B13: % Revenue | C13: =C12/C10 -> 0.113306 | D13: =D12/D10 -> 0.224 | E13: =E12/E10 -> 0.2375 | F13: =F12/F10 -> 0.25 | G13: =G12/G10 -> 0.263
B14: D&A | C14: =$H$55*C10 -> 101.18744 | D14: =$H$55*D10 -> 94.13041 | E14: =$H$55*E10 -> 97.772245 | F14: =$H$55*F10 -> 102.1158 | G14: =$H$55*G10 -> 106.6194 | J14: Cost of common equity | K14: =K10+(K11*K12) -> 0.11686386
B15: % Revenue | C15: =C14/C10 -> 0.0752 | D15: =D14/D10 -> 0.0752 | E15: =E14/E10 -> 0.0752 | F15: =F14/F10 -> 0.0752 | G15: =G14/G10 -> 0.0752 | J15: % Common Equity | K15: =K34/K47 -> 0.60180066
B16: Change in Net Working Capital | C16: 6.2228791 | D16: -0.024637486 | E16: 7.533984 | F16: 8.5111848 | G16: 9.0081977
B17: % Revenue | C17: 0.0046246897 | D17: -1.9682682e-05 | E17: 0.0057946464 | F17: 0.0062677966 | G17: 0.0063535947 | J17: Pre-tax cost of debt | K17: =K49/K33 -> 0.058389528
B18: CapEx | C18: 67.278882 | D18: 62.586709 | E18: 65.008142 | F18: 67.896147 | G18: 70.89056 | J18: Tax-rate | K18: 0.276
B19: % Revenue | C19: 0.05 | D19: 0.05 | E19: 0.05 | F19: 0.05 | G19: 0.05 | J19: After-tax cost of debt | K19: =K17*(1-K18) -> 0.042274018
J20: % Debt | K20: =K33/K47 -> 0.39819934
B21: Unlevered Free Cash Flow | C21: =C12+C14-C16-C18 -> 180.1477 | D21: =D12+D14-D16-D18 -> 311.9568 | E21: =E12+E14-E16-E18 -> 334.01879 | F21: =F12+F14-F16-F18 -> 365.18921 | G21: =G12+G14-G16-G18 -> 399.60499
B22: % Revenue | C22: =C21/H62 -> 0.13388131 | D22: =D21/I62 -> 0.24921968 | E22: =E21/J62 -> 0.25690535 | F22: =F21/K62 -> 0.2689322 | G22: =G21/L62 -> 0.28184641 | J22: Cost of preferred equity | K22: 0
J23: % preferred equity | K23: 0
B24: Discounted FCF | C24: =C21/(1+$K$25)^1 -> 165.70452 | D24: =D21/(1+$K$25)^2 -> 263.94032 | E24: =E21/(1+$K$25)^3 -> 259.94881 | F24: =F21/(1+$K$25)^4 -> 261.42102 | G24: =G21/(1+$K$25)^5 -> 263.12318
J25: WACC | K25: =K15*K14+K20*K19 -> 0.087162236
B26: Sum of Discounted FCFs | C26: =SUM(C24:G24) -> 1214.1378
B27: Terminal Value | C27: =(G24 * (1+$K$27))/($K$25-$K$27) -> 4160.7509 | J27: Perpetuity Growth Rate | K27: 0.0225
B28: PV of Terminal Value | C28: =C27/(1+$K$25)^5 -> 2739.6805
B29: Implied Enterprise Value | C29: =C26+C28 -> 3953.8184
B30: TV as a % of EV | C30: =C28/C29 -> 0.69292018 | J30: Enterprise Value
J31: Share price | K31: 52.25
B32: Cash & Cash Equivalents | C32: 68 | J32: Shares outstanding (diluted) | K32: 36.47
B33: Debt | C33: =K33 -> 1260.5 | J33: Total debt | K33: =102+1158.5 -> 1260.5
B34: Minority Interests | C34: 0 | J34: Market Cap | K34: 1905
B35: Preferred Equity | C35: 0
B37: Implied Equity Value | C37: =C29+C32-C33-C34-C35 -> 2761.3184
B38: Diluted Shares Outstanding | C38: 36.323
B40: Implied Share Price | C40: =C37/C38 -> 76.021209
B41: Current Share Price | C41: 52.25
B42: Premium (Discount) | C42: =(C40-C41)/C41 -> 0.45495136
C47: 2020 | D47: 2021 | E47: 2022 | F47: 2023 | G47: 2024 | J47: Total Capital | K47: =K34+K33 -> 3165.5
B48: EBIT | C48: 210.5829 | D48: 280.38846 | E48: 308.78867 | F48: 339.48073 | G48: 372.88435 | J48: Interest expense, net | K48: 18.4
B49: Average Historical Effective Tax Rate | C49: 0.276 | J49: Annualized interest expense | K49: =K48*4 -> 73.6
J51: Cost of Equity (CAPM) | K51: =K10+K11*K12 -> 0.11686386
B55: Depreciation and Amortization | C55: 0.0824 | D55: 0.079 | E55: 0.0652 | F55: 0.0726 | G55: 0.077 | H55: 0.0752
B57: Net Working Capital | C57: 173.6 | D57: 200.2 | E57: 304 | F57: 284.2 | G57: 222.4 | H57: 228.62288 | I57: 228.59824 | J57: 236.13223 | K57: 244.64341 | L57: 253.65161
B58: Chng. In NWC | D58: 26.6 | E58: 103.8 | F58: -19.8 | G58: -61.8 | H58: 6.2228791 | I58: -0.024637486 | J58: 7.533984 | K58: 8.5111848 | L58: 9.0081977
...
